[2025-01-13T14:15:05.172+0000] {taskinstance.py:1159} INFO - Dependencies all met for dep_context=non-requeueable deps ti=<TaskInstance: finflow_source_data_pipeline.generate_account_data manual__2025-01-13T14:14:38.498857+00:00 [queued]>
[2025-01-13T14:15:05.286+0000] {taskinstance.py:1159} INFO - Dependencies all met for dep_context=requeueable deps ti=<TaskInstance: finflow_source_data_pipeline.generate_account_data manual__2025-01-13T14:14:38.498857+00:00 [queued]>
[2025-01-13T14:15:05.288+0000] {taskinstance.py:1361} INFO - Starting attempt 1 of 2
[2025-01-13T14:15:05.404+0000] {taskinstance.py:1382} INFO - Executing <Task(PythonOperator): generate_account_data> on 2025-01-13 14:14:38.498857+00:00
[2025-01-13T14:15:05.456+0000] {standard_task_runner.py:57} INFO - Started process 2086 to run task
[2025-01-13T14:15:05.471+0000] {standard_task_runner.py:84} INFO - Running: ['***', 'tasks', 'run', 'finflow_source_data_pipeline', 'generate_account_data', 'manual__2025-01-13T14:14:38.498857+00:00', '--job-id', '240', '--raw', '--subdir', 'DAGS_FOLDER/finflow.py', '--cfg-path', '/tmp/tmppdk94zop']
[2025-01-13T14:15:05.499+0000] {standard_task_runner.py:85} INFO - Job 240: Subtask generate_account_data
[2025-01-13T14:15:05.788+0000] {task_command.py:416} INFO - Running <TaskInstance: finflow_source_data_pipeline.generate_account_data manual__2025-01-13T14:14:38.498857+00:00 [running]> on host ab4e86dc450e
[2025-01-13T14:15:06.012+0000] {taskinstance.py:1662} INFO - Exporting env vars: AIRFLOW_CTX_DAG_OWNER='***' AIRFLOW_CTX_DAG_ID='finflow_source_data_pipeline' AIRFLOW_CTX_TASK_ID='generate_account_data' AIRFLOW_CTX_EXECUTION_DATE='2025-01-13T14:14:38.498857+00:00' AIRFLOW_CTX_TRY_NUMBER='1' AIRFLOW_CTX_DAG_RUN_ID='manual__2025-01-13T14:14:38.498857+00:00'
[2025-01-13T14:15:06.014+0000] {finflow.py:68} INFO - Starting data generation for generate_account_data
[2025-01-13T14:15:06.093+0000] {finflow.py:73} ERROR - Error in data generation for generate_account_data: name 'fake' is not defined
[2025-01-13T14:15:06.094+0000] {taskinstance.py:1937} ERROR - Task failed with exception
Traceback (most recent call last):
  File "/opt/airflow/dags/finflow.py", line 69, in wrapper
    result = func(*args, **kwargs)
  File "/opt/airflow/dags/finflow.py", line 298, in generate_account_data
    'opened_date': fake.date_between(start_date='-5y', end_date='today'),
NameError: name 'fake' is not defined

During handling of the above exception, another exception occurred:

Traceback (most recent call last):
  File "/home/airflow/.local/lib/python3.8/site-packages/airflow/operators/python.py", line 192, in execute
    return_value = self.execute_callable()
  File "/home/airflow/.local/lib/python3.8/site-packages/airflow/operators/python.py", line 209, in execute_callable
    return self.python_callable(*self.op_args, **self.op_kwargs)
  File "/opt/airflow/dags/finflow.py", line 74, in wrapper
    raise DataGenerationError(f"Failed to generate data in {func.__name__}: {str(e)}")
unusual_prefix_e3732bef98af2b043177fdcca303303d50b4bb69_finflow.DataGenerationError: Failed to generate data in generate_account_data: name 'fake' is not defined
[2025-01-13T14:15:06.110+0000] {taskinstance.py:1400} INFO - Marking task as UP_FOR_RETRY. dag_id=finflow_source_data_pipeline, task_id=generate_account_data, execution_date=20250113T141438, start_date=20250113T141505, end_date=20250113T141506
[2025-01-13T14:15:06.143+0000] {standard_task_runner.py:104} ERROR - Failed to execute job 240 for task generate_account_data (Failed to generate data in generate_account_data: name 'fake' is not defined; 2086)
[2025-01-13T14:15:06.198+0000] {local_task_job_runner.py:228} INFO - Task exited with return code 1
[2025-01-13T14:15:06.337+0000] {taskinstance.py:2778} INFO - 0 downstream tasks scheduled from follow-on schedule check
