[2025-01-11T21:56:22.050+0000] {taskinstance.py:1159} INFO - Dependencies all met for dep_context=non-requeueable deps ti=<TaskInstance: finflow_analytics_pipeline.generate_account_balances scheduled__2025-01-10T21:54:42.447412+00:00 [queued]>
[2025-01-11T21:56:22.404+0000] {taskinstance.py:1159} INFO - Dependencies all met for dep_context=requeueable deps ti=<TaskInstance: finflow_analytics_pipeline.generate_account_balances scheduled__2025-01-10T21:54:42.447412+00:00 [queued]>
[2025-01-11T21:56:22.423+0000] {taskinstance.py:1361} INFO - Starting attempt 1 of 2
[2025-01-11T21:56:22.892+0000] {taskinstance.py:1382} INFO - Executing <Task(PythonOperator): generate_account_balances> on 2025-01-10 21:54:42.447412+00:00
[2025-01-11T21:56:23.159+0000] {standard_task_runner.py:57} INFO - Started process 425 to run task
[2025-01-11T21:56:23.323+0000] {standard_task_runner.py:84} INFO - Running: ['***', 'tasks', 'run', 'finflow_analytics_pipeline', 'generate_account_balances', 'scheduled__2025-01-10T21:54:42.447412+00:00', '--job-id', '26', '--raw', '--subdir', 'DAGS_FOLDER/finflow.py', '--cfg-path', '/tmp/tmpggdkktnq']
[2025-01-11T21:56:23.527+0000] {standard_task_runner.py:85} INFO - Job 26: Subtask generate_account_balances
[2025-01-11T21:56:24.721+0000] {task_command.py:416} INFO - Running <TaskInstance: finflow_analytics_pipeline.generate_account_balances scheduled__2025-01-10T21:54:42.447412+00:00 [running]> on host 4e62577a6f21
[2025-01-11T21:56:26.319+0000] {taskinstance.py:1662} INFO - Exporting env vars: AIRFLOW_CTX_DAG_OWNER='***' AIRFLOW_CTX_DAG_ID='finflow_analytics_pipeline' AIRFLOW_CTX_TASK_ID='generate_account_balances' AIRFLOW_CTX_EXECUTION_DATE='2025-01-10T21:54:42.447412+00:00' AIRFLOW_CTX_TRY_NUMBER='1' AIRFLOW_CTX_DAG_RUN_ID='scheduled__2025-01-10T21:54:42.447412+00:00'
[2025-01-11T21:56:29.067+0000] {taskinstance.py:1937} ERROR - Task failed with exception
Traceback (most recent call last):
  File "/home/airflow/.local/lib/python3.8/site-packages/airflow/operators/python.py", line 192, in execute
    return_value = self.execute_callable()
  File "/home/airflow/.local/lib/python3.8/site-packages/airflow/operators/python.py", line 209, in execute_callable
    return self.python_callable(*self.op_args, **self.op_kwargs)
  File "/opt/airflow/dags/finflow.py", line 284, in generate_account_balances
    transactions_df = pd.read_parquet(transactions_file)
  File "/home/airflow/.local/lib/python3.8/site-packages/pandas/io/parquet.py", line 509, in read_parquet
    return impl.read(
  File "/home/airflow/.local/lib/python3.8/site-packages/pandas/io/parquet.py", line 227, in read
    pa_table = self.api.parquet.read_table(
  File "/home/airflow/.local/lib/python3.8/site-packages/pyarrow/parquet/core.py", line 2926, in read_table
    dataset = _ParquetDatasetV2(
  File "/home/airflow/.local/lib/python3.8/site-packages/pyarrow/parquet/core.py", line 2477, in __init__
    self._dataset = ds.dataset(path_or_paths, filesystem=filesystem,
  File "/home/airflow/.local/lib/python3.8/site-packages/pyarrow/dataset.py", line 782, in dataset
    raise TypeError(
TypeError: Expected a path-like, list of path-likes or a list of Datasets instead of the given type: NoneType
[2025-01-11T21:56:29.228+0000] {taskinstance.py:1400} INFO - Marking task as UP_FOR_RETRY. dag_id=finflow_analytics_pipeline, task_id=generate_account_balances, execution_date=20250110T215442, start_date=20250111T215622, end_date=20250111T215629
[2025-01-11T21:56:29.475+0000] {standard_task_runner.py:104} ERROR - Failed to execute job 26 for task generate_account_balances (Expected a path-like, list of path-likes or a list of Datasets instead of the given type: NoneType; 425)
[2025-01-11T21:56:29.801+0000] {local_task_job_runner.py:228} INFO - Task exited with return code 1
[2025-01-11T21:56:30.391+0000] {taskinstance.py:2778} INFO - 0 downstream tasks scheduled from follow-on schedule check
